#VRML_SIM R2025a utf8

EXTERNPROTO "https://raw.githubusercontent.com/cyberbotics/webots/R2025a/projects/objects/backgrounds/protos/TexturedBackground.proto"
EXTERNPROTO "https://raw.githubusercontent.com/cyberbotics/webots/R2025a/projects/objects/backgrounds/protos/TexturedBackgroundLight.proto"

WorldInfo {
  title "平坦地形导航测试 - Flat Terrain Navigation"
  basicTimeStep 32
  contactProperties [
    ContactProperties {
      material1 "ground"
      coulombFriction [
        0.8
      ]
      softCFM 0.0001
    }
  ]
}
Viewpoint {
  orientation -0.4 -0.4 0.82 1.9
  position 15 -15 12
  follow "adaptive_robot"
  followType "Pan and Tilt Shot"
  followSmoothness 0.3
}
TexturedBackground {
  texture "noon_cloudy_countryside"
  luminosity 1.2
}
TexturedBackgroundLight {
  texture "noon_cloudy_countryside"
  castShadows TRUE
}
DirectionalLight {
  direction -0.4 -0.5 -1
  color 1.0 0.96 0.88
  intensity 2.5
  castShadows TRUE
}
DEF GROUND Solid {
  translation 0 0 -0.05
  children [
    Shape {
      appearance PBRAppearance {
        baseColorMap ImageTexture {
          url [
            "https://raw.githubusercontent.com/cyberbotics/webots/R2025a/projects/default/worlds/textures/grass.jpg"
          ]
        }
        roughness 0.9
        metalness 0
        textureTransform TextureTransform {
          scale 50 50
        }
      }
      geometry DEF GROUND_BOX Box {
        size 100 100 0.1
      }
    }
  ]
  name "ground"
  contactMaterial "ground"
  boundingObject USE GROUND_BOX
  locked TRUE
}
DEF WALL_NORTH Solid {
  translation 0 50 0.5
  children [
    Shape {
      appearance PBRAppearance {
        baseColor 0.8 0.8 0.8
        roughness 0.5
      }
      geometry Box {
        size 100 0.2 1
      }
    }
  ]
  name "wall_north"
  boundingObject Box {
    size 100 0.2 1
  }
}
DEF WALL_SOUTH Solid {
  translation 0 -50 0.5
  children [
    Shape {
      appearance PBRAppearance {
        baseColor 0.8 0.8 0.8
        roughness 0.5
      }
      geometry Box {
        size 100 0.2 1
      }
    }
  ]
  name "wall_south"
  boundingObject Box {
    size 100 0.2 1
  }
}
DEF WALL_EAST Solid {
  translation 50 0 0.5
  children [
    Shape {
      appearance PBRAppearance {
        baseColor 0.8 0.8 0.8
        roughness 0.5
      }
      geometry Box {
        size 0.2 100 1
      }
    }
  ]
  name "wall_east"
  boundingObject Box {
    size 0.2 100 1
  }
}
DEF WALL_WEST Solid {
  translation -50 0 0.5
  children [
    Shape {
      appearance PBRAppearance {
        baseColor 0.8 0.8 0.8
        roughness 0.5
      }
      geometry Box {
        size 0.2 100 1
      }
    }
  ]
  name "wall_west"
  boundingObject Box {
    size 0.2 100 1
  }
}
DEF TARGET_MARKER_1 Solid {
  translation 8 0 0.05
  children [
    Shape {
      appearance PBRAppearance {
        baseColor 1 0 0
        emissiveColor 0.5 0 0
      }
      geometry Cylinder {
        height 0.1
        radius 0.3
      }
    }
  ]
  name "target_1"
}
DEF TARGET_MARKER_2 Solid {
  translation 8 8 0.05
  children [
    Shape {
      appearance PBRAppearance {
        baseColor 1 0.5 0
        emissiveColor 0.5 0.25 0
      }
      geometry Cylinder {
        height 0.1
        radius 0.3
      }
    }
  ]
  name "target_2"
}
DEF TARGET_MARKER_3 Solid {
  translation -8 8 0.05
  children [
    Shape {
      appearance PBRAppearance {
        baseColor 1 1 0
        emissiveColor 0.5 0.5 0
      }
      geometry Cylinder {
        height 0.1
        radius 0.3
      }
    }
  ]
  name "target_3"
}
DEF TARGET_MARKER_4 Solid {
  translation -8 -8 0.05
  children [
    Shape {
      appearance PBRAppearance {
        baseColor 0 1 0
        emissiveColor 0 0.5 0
      }
      geometry Cylinder {
        height 0.1
        radius 0.3
      }
    }
  ]
  name "target_4"
}
DEF TARGET_MARKER_5 Solid {
  translation 8 -8 0.05
  children [
    Shape {
      appearance PBRAppearance {
        baseColor 0 0.5 1
        emissiveColor 0 0.25 0.5
      }
      geometry Cylinder {
        height 0.1
        radius 0.3
      }
    }
  ]
  name "target_5"
}
Robot {
  translation 0 0 0.15
  rotation 0 0 1 0
  children [
    DEF BODY Shape {
      appearance PBRAppearance {
        baseColor 0.2 0.4 0.8
        roughness 0.5
        metalness 0.3
      }
      geometry Box {
        size 0.4 0.3 0.1
      }
    }
    DEF LIDAR Lidar {
      translation 0 0 0.08
      horizontalResolution 360
      fieldOfView 6.2832
      numberOfLayers 1
      maxRange 15
    }
    DEF GPS GPS {
      translation 0 0 0.05
    }
    DEF COMPASS Compass {
      translation 0 0 0.05
    }
    DEF IMU InertialUnit {
      translation 0 0 0.05
    }
    DEF WHEEL_FL HingeJoint {
      jointParameters HingeJointParameters {
        axis 0 1 0
        anchor 0.15 0.18 -0.03
      }
      device [
        RotationalMotor {
          name "wheel_fl"
          maxVelocity 15
        }
      ]
      endPoint Solid {
        translation 0.15 0.18 -0.03
        rotation 1 0 0 1.5708
        children [
          Shape {
            appearance PBRAppearance {
              baseColor 0.1 0.1 0.1
              roughness 0.8
            }
            geometry Cylinder {
              height 0.04
              radius 0.06
            }
          }
        ]
        name "wheel_fl"
        boundingObject Cylinder {
          height 0.04
          radius 0.06
        }
        physics Physics {
          density 500
        }
      }
    }
    DEF WHEEL_FR HingeJoint {
      jointParameters HingeJointParameters {
        axis 0 1 0
        anchor 0.15 -0.18 -0.03
      }
      device [
        RotationalMotor {
          name "wheel_fr"
          maxVelocity 15
        }
      ]
      endPoint Solid {
        translation 0.15 -0.18 -0.03
        rotation 1 0 0 1.5708
        children [
          Shape {
            appearance PBRAppearance {
              baseColor 0.1 0.1 0.1
              roughness 0.8
            }
            geometry Cylinder {
              height 0.04
              radius 0.06
            }
          }
        ]
        name "wheel_fr"
        boundingObject Cylinder {
          height 0.04
          radius 0.06
        }
        physics Physics {
          density 500
        }
      }
    }
    DEF WHEEL_RL HingeJoint {
      jointParameters HingeJointParameters {
        axis 0 1 0
        anchor -0.15 0.18 -0.03
      }
      device [
        RotationalMotor {
          name "wheel_rl"
          maxVelocity 15
        }
      ]
      endPoint Solid {
        translation -0.15 0.18 -0.03
        rotation 1 0 0 1.5708
        children [
          Shape {
            appearance PBRAppearance {
              baseColor 0.1 0.1 0.1
              roughness 0.8
            }
            geometry Cylinder {
              height 0.04
              radius 0.06
            }
          }
        ]
        name "wheel_rl"
        boundingObject Cylinder {
          height 0.04
          radius 0.06
        }
        physics Physics {
          density 500
        }
      }
    }
    DEF WHEEL_RR HingeJoint {
      jointParameters HingeJointParameters {
        axis 0 1 0
        anchor -0.15 -0.18 -0.03
      }
      device [
        RotationalMotor {
          name "wheel_rr"
          maxVelocity 15
        }
      ]
      endPoint Solid {
        translation -0.15 -0.18 -0.03
        rotation 1 0 0 1.5708
        children [
          Shape {
            appearance PBRAppearance {
              baseColor 0.1 0.1 0.1
              roughness 0.8
            }
            geometry Cylinder {
              height 0.04
              radius 0.06
            }
          }
        ]
        name "wheel_rr"
        boundingObject Cylinder {
          height 0.04
          radius 0.06
        }
        physics Physics {
          density 500
        }
      }
    }
  ]
  name "adaptive_robot"
  boundingObject Box {
    size 0.4 0.3 0.1
  }
  physics Physics {
    density 1000
  }
  controller "adaptive_navigator"
}
